Workbook

Sheet Employee Master
A1: Employee ID | B1: Full Name | C1: Email | D1: Phone | E1: Department | F1: Job Title | G1: Employment Type | H1: Date of Joining | I1: Manager | J1: Location | K1: Salary | L1: Emergency Contact | M1: Emergency Phone | N1: Status
A2: EMP001 | B2: Rajesh Kumar | C2: rajesh.kumar@company.com | D2: 9876543210 | E2: Engineering | F2: Senior Engineer | G2: Full-Time | H2: 44635 | I2: Amit Sharma | J2: Bangalore | K2: 95000 | L2: Priya Kumar | M2: 9876543211 | N2: Active
A3: EMP002 | B3: Priya Sharma | C3: priya.sharma@company.com | D3: 9876543212 | E3: Sales | F3: Sales Manager | G3: Full-Time | H3: 44348 | I3: Vikram Singh | J3: Mumbai | K3: 85000 | L3: Rahul Sharma | M3: 9876543213 | N3: Active
A4: EMP003 | B4: Amit Patel | C4: amit.patel@company.com | D4: 9876543214 | E4: Marketing | F4: Marketing Manager | G4: Full-Time | H4: 43850 | I4: Neha Gupta | J4: Delhi | K4: 78000 | L4: Sneha Patel | M4: 9876543215 | N4: Active
A5: EMP004 | B5: Neha Singh | C5: neha.singh@company.com | D5: 9876543216 | E5: HR | F5: HR Manager | G5: Full-Time | H5: 43718 | I5: CEO | J5: Bangalore | K5: 92000 | L5: Karan Singh | M5: 9876543217 | N5: Active
A6: EMP005 | B6: Vikram Reddy | C6: vikram.reddy@company.com | D6: 9876543218 | E6: Finance | F6: Finance Manager | G6: Full-Time | H6: 44505 | I6: CFO | J6: Hyderabad | K6: 98000 | L6: Lakshmi Reddy | M6: 9876543219 | N6: Active
A7: EMP006 | B7: Ananya Iyer | C7: ananya.iyer@company.com | D7: 9876543220 | E7: Engineering | F7: Software Engineer | G7: Full-Time | H7: 44971 | I7: Rajesh Kumar | J7: Bangalore | K7: 72000 | L7: Suresh Iyer | M7: 9876543221 | N7: Active
A8: EMP007 | B8: Karthik Menon | C8: karthik.menon@company.com | D8: 9876543222 | E8: Sales | F8: Sales Executive | G8: Full-Time | H8: 45054 | I8: Priya Sharma | J8: Pune | K8: 55000 | L8: Meera Menon | M8: 9876543223 | N8: Active
A9: EMP008 | B9: Divya Nair | C9: divya.nair@company.com | D9: 9876543224 | E9: Marketing | F9: Digital Marketer | G9: Contract | H9: 45139 | I9: Amit Patel | J9: Mumbai | K9: 48000 | L9: Anil Nair | M9: 9876543225 | N9: Active
A10: EMP009 | B10: Rahul Verma | C10: rahul.verma@company.com | D10: 9876543226 | E10: Engineering | F10: QA Engineer | G10: Full-Time | H10: 44905 | I10: Rajesh Kumar | J10: Delhi | K10: 68000 | L10: Pooja Verma | M10: 9876543227 | N10: Active
A11: EMP010 | B11: Sneha Desai | C11: sneha.desai@company.com | D11: 9876543228 | E11: HR | F11: Recruiter | G11: Full-Time | H11: 45005 | I11: Neha Singh | J11: Bangalore | K11: 52000 | L11: Nitin Desai | M11: 9876543229 | N11: Active
A12: EMP011 | B12: Arjun Kapoor | C12: arjun.kapoor@company.com | D12: 9876543230 | E12: Operations | F12: Operations Manager | G12: Full-Time | H12: 44392 | I12: COO | J12: Mumbai | K12: 88000 | L12: Kavita Kapoor | M12: 9876543231 | N12: Active
A13: EMP012 | B13: Pooja Agarwal | C13: pooja.agarwal@company.com | D13: 9876543232 | E13: Finance | F13: Accountant | G13: Full-Time | H13: 44809 | I13: Vikram Reddy | J13: Hyderabad | K13: 58000 | L13: Ravi Agarwal | M13: 9876543233 | N13: Active
... A16: EMP015 | B16: Siddharth Roy | C16: siddharth.roy@company.com | D16: 9876543238 | E16: Marketing | F16: Content Writer | G16: Intern | H16: 45170 | I16: Amit Patel | J16: Delhi | K16: 25000 | L16: Meena Roy | M16: 9876543239 | N16: Active

Sheet Attendance Tracker
A1: Employee ID | B1: Employee Name | C1: Date | D1: Check-In | E1: Check-Out | F1: Total Hours | G1: Status | H1: Overtime Hours | I1: Notes
A2: EMP001 | B2: Rajesh Kumar | C2: 46126.966 | G2: Absent | I2: Sick leave
A3: EMP002 | B3: Priya Sharma | C3: 46126.966 | D3: 09:00 | E3: 18:00 | F3: =(TIME(VALUE(MID(E3,1,2)),VALUE(MID(E3,4,2)),0)-TIME(VALUE(MID(D3,1,2)),VALUE(MID(D3,4,2)),0))*24 | G3: Present | H3: =IF(F3>8,F3-8,0)
A4: EMP003 | B4: Amit Patel | C4: 46126.966 | D4: 09:00 | E4: 18:00 | F4: =(TIME(VALUE(MID(E4,1,2)),VALUE(MID(E4,4,2)),0)-TIME(VALUE(MID(D4,1,2)),VALUE(MID(D4,4,2)),0))*24 | G4: Present | H4: =IF(F4>8,F4-8,0)
A5: EMP004 | B5: Neha Singh | C5: 46126.966 | D5: 09:00 | E5: 13:00 | F5: =(TIME(VALUE(MID(E5,1,2)),VALUE(MID(E5,4,2)),0)-TIME(VALUE(MID(D5,1,2)),VALUE(MID(D5,4,2)),0))*24 | G5: Half Day | H5: =IF(F5>8,F5-8,0) | I5: Personal work
A6: EMP005 | B6: Vikram Reddy | C6: 46126.966 | G6: Absent | I6: Sick leave
A7: EMP006 | B7: Ananya Iyer | C7: 46126.966 | D7: 09:00 | E7: 18:00 | F7: =(TIME(VALUE(MID(E7,1,2)),VALUE(MID(E7,4,2)),0)-TIME(VALUE(MID(D7,1,2)),VALUE(MID(D7,4,2)),0))*24 | G7: Present | H7: =IF(F7>8,F7-8,0)
A8: EMP007 | B8: Karthik Menon | C8: 46126.966 | G8: Absent | I8: Sick leave
A9: EMP008 | B9: Divya Nair | C9: 46126.966 | D9: 09:00 | E9: 18:00 | F9: =(TIME(VALUE(MID(E9,1,2)),VALUE(MID(E9,4,2)),0)-TIME(VALUE(MID(D9,1,2)),VALUE(MID(D9,4,2)),0))*24 | G9: Present | H9: =IF(F9>8,F9-8,0)
A10: EMP009 | B10: Rahul Verma | C10: 46126.966 | D10: 09:00 | E10: 18:00 | F10: =(TIME(VALUE(MID(E10,1,2)),VALUE(MID(E10,4,2)),0)-TIME(VALUE(MID(D10,1,2)),VALUE(MID(D10,4,2)),0))*24 | G10: Present | H10: =IF(F10>8,F10-8,0)
A11: EMP010 | B11: Sneha Desai | C11: 46126.966 | D11: 09:00 | E11: 18:00 | F11: =(TIME(VALUE(MID(E11,1,2)),VALUE(MID(E11,4,2)),0)-TIME(VALUE(MID(D11,1,2)),VALUE(MID(D11,4,2)),0))*24 | G11: Present | H11: =IF(F11>8,F11-8,0)
A12: EMP001 | B12: Rajesh Kumar | C12: 46127.966 | D12: 09:00 | E12: 18:00 | F12: =(TIME(VALUE(MID(E12,1,2)),VALUE(MID(E12,4,2)),0)-TIME(VALUE(MID(D12,1,2)),VALUE(MID(D12,4,2)),0))*24 | G12: Present | H12: =IF(F12>8,F12-8,0)
A13: EMP002 | B13: Priya Sharma | C13: 46127.966 | D13: 09:45 | E13: 18:00 | F13: =(TIME(VALUE(MID(E13,1,2)),VALUE(MID(E13,4,2)),0)-TIME(VALUE(MID(D13,1,2)),VALUE(MID(D13,4,2)),0))*24 | G13: Late | H13: =IF(F13>8,F13-8,0) | I13: Traffic delay
A14: EMP003 | B14: Amit Patel | C14: 46127.966 | D14: 09:00 | E14: 13:00 | F14: =(TIME(VALUE(MID(E14,1,2)),VALUE(MID(E14,4,2)),0)-TIME(VALUE(MID(D14,1,2)),VALUE(MID(D14,4,2)),0))*24 | G14: Half Day | H14: =IF(F14>8,F14-8,0) | I14: Personal work
A15: EMP004 | B15: Neha Singh | C15: 46127.966 | D15: 09:00 | E15: 18:00 | F15: =(TIME(VALUE(MID(E15,1,2)),VALUE(MID(E15,4,2)),0)-TIME(VALUE(MID(D15,1,2)),VALUE(MID(D15,4,2)),0))*24 | G15: Present | H15: =IF(F15>8,F15-8,0)
A16: EMP005 | B16: Vikram Reddy | C16: 46127.966 | D16: 09:00 | E16: 18:00 | F16: =(TIME(VALUE(MID(E16,1,2)),VALUE(MID(E16,4,2)),0)-TIME(VALUE(MID(D16,1,2)),VALUE(MID(D16,4,2)),0))*24 | G16: Present | H16: =IF(F16>8,F16-8,0)
A17: EMP006 | B17: Ananya Iyer | C17: 46127.966 | D17: 09:45 | E17: 18:00 | F17: =(TIME(VALUE(MID(E17,1,2)),VALUE(MID(E17,4,2)),0)-TIME(VALUE(MID(D17,1,2)),VALUE(MID(D17,4,2)),0))*24 | G17: Late | H17: =IF(F17>8,F17-8,0) | I17: Traffic delay
A18: EMP007 | B18: Karthik Menon | C18: 46127.966 | D18: 09:00 | E18: 18:00 | F18: =(TIME(VALUE(MID(E18,1,2)),VALUE(MID(E18,4,2)),0)-TIME(VALUE(MID(D18,1,2)),VALUE(MID(D18,4,2)),0))*24 | G18: Present | H18: =IF(F18>8,F18-8,0)
A19: EMP008 | B19: Divya Nair | C19: 46127.966 | D19: 09:00 | E19: 18:00 | F19: =(TIME(VALUE(MID(E19,1,2)),VALUE(MID(E19,4,2)),0)-TIME(VALUE(MID(D19,1,2)),VALUE(MID(D19,4,2)),0))*24 | G19: Present | H19: =IF(F19>8,F19-8,0)
A20: EMP009 | B20: Rahul Verma | C20: 46127.966 | D20: 09:00 | E20: 18:00 | F20: =(TIME(VALUE(MID(E20,1,2)),VALUE(MID(E20,4,2)),0)-TIME(VALUE(MID(D20,1,2)),VALUE(MID(D20,4,2)),0))*24 | G20: Present | H20: =IF(F20>8,F20-8,0)
A21: EMP010 | B21: Sneha Desai | C21: 46127.966 | D21: 09:00 | E21: 18:00 | F21: =(TIME(VALUE(MID(E21,1,2)),VALUE(MID(E21,4,2)),0)-TIME(VALUE(MID(D21,1,2)),VALUE(MID(D21,4,2)),0))*24 | G21: Present | H21: =IF(F21>8,F21-8,0)
A22: EMP001 | B22: Rajesh Kumar | C22: 46128.966 | D22: 09:00 | E22: 18:00 | F22: =(TIME(VALUE(MID(E22,1,2)),VALUE(MID(E22,4,2)),0)-TIME(VALUE(MID(D22,1,2)),VALUE(MID(D22,4,2)),0))*24 | G22: Present | H22: =IF(F22>8,F22-8,0)
A23: EMP002 | B23: Priya Sharma | C23: 46128.966 | D23: 09:45 | E23: 18:00 | F23: =(TIME(VALUE(MID(E23,1,2)),VALUE(MID(E23,4,2)),0)-TIME(VALUE(MID(D23,1,2)),VALUE(MID(D23,4,2)),0))*24 | G23: Late | H23: =IF(F23>8,F23-8,0) | I23: Traffic delay
A24: EMP003 | B24: Amit Patel | C24: 46128.966 | D24: 09:00 | E24: 18:00 | F24: =(TIME(VALUE(MID(E24,1,2)),VALUE(MID(E24,4,2)),0)-TIME(VALUE(MID(D24,1,2)),VALUE(MID(D24,4,2)),0))*24 | G24: Present | H24: =IF(F24>8,F24-8,0)
A25: EMP004 | B25: Neha Singh | C25: 46128.966 | D25: 09:00 | E25: 18:00 | F25: =(TIME(VALUE(MID(E25,1,2)),VALUE(MID(E25,4,2)),0)-TIME(VALUE(MID(D25,1,2)),VALUE(MID(D25,4,2)),0))*24 | G25: Present | H25: =IF(F25>8,F25-8,0)
A26: EMP005 | B26: Vikram Reddy | C26: 46128.966 | D26: 09:00 | E26: 13:00 | F26: =(TIME(VALUE(MID(E26,1,2)),VALUE(MID(E26,4,2)),0)-TIME(VALUE(MID(D26,1,2)),VALUE(MID(D26,4,2)),0))*24 | G26: Half Day | H26: =IF(F26>8,F26-8,0) | I26: Personal work
A27: EMP006 | B27: Ananya Iyer | C27: 46128.966 | D27: 09:00 | E27: 13:00 | F27: =(TIME(VALUE(MID(E27,1,2)),VALUE(MID(E27,4,2)),0)-TIME(VALUE(MID(D27,1,2)),VALUE(MID(D27,4,2)),0))*24 | G27: Half Day | H27: =IF(F27>8,F27-8,0) | I27: Personal work
A28: EMP007 | B28: Karthik Menon | C28: 46128.966 | D28: 09:45 | E28: 18:00 | F28: =(TIME(VALUE(MID(E28,1,2)),VALUE(MID(E28,4,2)),0)-TIME(VALUE(MID(D28,1,2)),VALUE(MID(D28,4,2)),0))*24 | G28: Late | H28: =IF(F28>8,F28-8,0) | I28: Traffic delay
A29: EMP008 | B29: Divya Nair | C29: 46128.966 | D29: 09:00 | E29: 18:00 | F29: =(TIME(VALUE(MID(E29,1,2)),VALUE(MID(E29,4,2)),0)-TIME(VALUE(MID(D29,1,2)),VALUE(MID(D29,4,2)),0))*24 | G29: Present | H29: =IF(F29>8,F29-8,0)
A30: EMP009 | B30: Rahul Verma | C30: 46128.966 | D30: 09:00 | E30: 18:00 | F30: =(TIME(VALUE(MID(E30,1,2)),VALUE(MID(E30,4,2)),0)-TIME(VALUE(MID(D30,1,2)),VALUE(MID(D30,4,2)),0))*24 | G30: Present | H30: =IF(F30>8,F30-8,0)
A31: EMP010 | B31: Sneha Desai | C31: 46128.966 | G31: Absent | I31: Sick leave
A32: EMP001 | B32: Rajesh Kumar | C32: 46129.966 | D32: 09:00 | E32: 18:00 | F32: =(TIME(VALUE(MID(E32,1,2)),VALUE(MID(E32,4,2)),0)-TIME(VALUE(MID(D32,1,2)),VALUE(MID(D32,4,2)),0))*24 | G32: Present | H32: =IF(F32>8,F32-8,0)
A33: EMP002 | B33: Priya Sharma | C33: 46129.966 | G33: Absent | I33: Sick leave
A34: EMP003 | B34: Amit Patel | C34: 46129.966 | D34: 09:00 | E34: 18:00 | F34: =(TIME(VALUE(MID(E34,1,2)),VALUE(MID(E34,4,2)),0)-TIME(VALUE(MID(D34,1,2)),VALUE(MID(D34,4,2)),0))*24 | G34: Present | H34: =IF(F34>8,F34-8,0)
A35: EMP004 | B35: Neha Singh | C35: 46129.966 | G35: Absent | I35: Sick leave
A36: EMP005 | B36: Vikram Reddy | C36: 46129.966 | D36: 09:00 | E36: 18:00 | F36: =(TIME(VALUE(MID(E36,1,2)),VALUE(MID(E36,4,2)),0)-TIME(VALUE(MID(D36,1,2)),VALUE(MID(D36,4,2)),0))*24 | G36: Present | H36: =IF(F36>8,F36-8,0)
A37: EMP006 | B37: Ananya Iyer | C37: 46129.966 | D37: 09:00 | E37: 18:00 | F37: =(TIME(VALUE(MID(E37,1,2)),VALUE(MID(E37,4,2)),0)-TIME(VALUE(MID(D37,1,2)),VALUE(MID(D37,4,2)),0))*24 | G37: Present | H37: =IF(F37>8,F37-8,0)
A38: EMP007 | B38: Karthik Menon | C38: 46129.966 | D38: 09:00 | E38: 13:00 | F38: =(TIME(VALUE(MID(E38,1,2)),VALUE(MID(E38,4,2)),0)-TIME(VALUE(MID(D38,1,2)),VALUE(MID(D38,4,2)),0))*24 | G38: Half Day | H38: =IF(F38>8,F38-8,0) | I38: Personal work
A39: EMP008 | B39: Divya Nair | C39: 46129.966 | D39: 09:00 | E39: 18:00 | F39: =(TIME(VALUE(MID(E39,1,2)),VALUE(MID(E39,4,2)),0)-TIME(VALUE(MID(D39,1,2)),VALUE(MID(D39,4,2)),0))*24 | G39: Present | H39: =IF(F39>8,F39-8,0)
A40: EMP009 | B40: Rahul Verma | C40: 46129.966 | D40: 09:00 | E40: 18:00 | F40: =(TIME(VALUE(MID(E40,1,2)),VALUE(MID(E40,4,2)),0)-TIME(VALUE(MID(D40,1,2)),VALUE(MID(D40,4,2)),0))*24 | G40: Present | H40: =IF(F40>8,F40-8,0)
...

Sheet Onboarding Pipeline
A1: Candidate Name | B1: Position | C1: Department | D1: Offer Date | E1: Joining Date | F1: Current Stage | G1: Document Verification | H1: IT Setup | I1: Training Assigned | J1: Manager Assignment | K1: Completion % | L1: Days to Complete | M1: Status
A2: Amit Verma | B2: Software Engineer | C2: Engineering | D2: 45296 | E2: 45323 | F2: IT Setup | G2: Complete | H2: In Progress | I2: Pending | J2: Complete | K2: =COUNTIF(G2:J2,"Complete")/4 | L2: =E2-TODAY() | M2: On Track
A3: Ria Kapoor | B3: Sales Executive | C3: Sales | D3: 45301 | E3: 45327 | F3: Training | G3: Complete | H3: Complete | I3: In Progress | J3: Complete | K3: =COUNTIF(G3:J3,"Complete")/4 | L3: =E3-TODAY() | M3: On Track
A4: Naveen Kumar | B4: Marketing Manager | C4: Marketing | D4: 45299 | E4: 45325 | F4: Manager Assignment | G4: Complete | H4: Complete | I4: Complete | J4: In Progress | K4: =COUNTIF(G4:J4,"Complete")/4 | L4: =E4-TODAY() | M4: On Track
A5: Simran Gill | B5: HR Coordinator | C5: HR | D5: 45303 | E5: 45330 | F5: Document Verification | G5: In Progress | H5: Pending | I5: Pending | J5: Pending | K5: =COUNTIF(G5:J5,"Complete")/4 | L5: =E5-TODAY() | M5: Delayed
A6: Aditya Menon | B6: Financial Analyst | C6: Finance | D6: 45306 | E6: 45332 | F6: Offer Accepted | G6: Pending | H6: Pending | I6: Pending | J6: Pending | K6: =COUNTIF(G6:J6,"Complete")/4 | L6: =E6-TODAY() | M6: On Track

Sheet Leave Management
A1: Employee ID | B1: Employee Name | C1: Leave Type | D1: Start Date | E1: End Date | F1: Days | G1: Reason | H1: Status | I1: Approved By | J1: Date Submitted
A2: EMP001 | B2: Rajesh Kumar | C2: Annual Leave | D2: 45337 | E2: 45342 | F2: =E2-D2+1 | G2: Family vacation | H2: Approved | I2: Amit Sharma | J2: 45323
A3: EMP006 | B3: Ananya Iyer | C3: Sick Leave | D3: 45330 | E3: 45331 | F3: =E3-D3+1 | G3: Flu | H3: Approved | I3: Rajesh Kumar | J3: 45329
A4: EMP007 | B4: Karthik Menon | C4: Casual Leave | D4: 45344 | E4: 45344 | F4: =E4-D4+1 | G4: Personal work | H4: Pending | J4: 45342
A5: EMP003 | B5: Amit Patel | C5: Annual Leave | D5: 45361 | E5: 45366 | F5: =E5-D5+1 | G5: Wedding anniversary | H5: Approved | I5: Neha Gupta | J5: 45347
A6: EMP010 | B6: Sneha Desai | C6: Comp Off | D6: 45350 | E6: 45350 | F6: =E6-D6+1 | G6: Weekend work compensation | H6: Approved | I6: Neha Singh | J6: 45348

Sheet HR Dashboard
A1: HR ANALYTICS DASHBOARD
A2: Report Date: | B2: =TODAY()
A4: KEY METRICS
A5: Total Employees | B5: =COUNTA('Employee Master'!A2:A16)
A6: Active Employees | B6: =COUNTIF('Employee Master'!N2:N16,"Active")
A7: Departments | B7: =COUNTA(UNIQUE('Employee Master'!E2:E16))
A8: Average Tenure (Years) | B8: =(TODAY()-AVERAGE('Employee Master'!H2:H16))/365
A9: Pending Onboarding | B9: =COUNTIF('Onboarding Pipeline'!M2:M6,"On Track")
A10: Pending Leave Requests | B10: =COUNTIF('Leave Management'!H2:H6,"Pending")
A12: DEPARTMENT BREAKDOWN
A13: Department | B13: Employee Count | C13: Avg Salary | E13: ATTENDANCE SUMMARY (Last 10 Days)
A14: Engineering | B14: =COUNTIF('Employee Master'!E:E,A14) | C14: =AVERAGEIF('Employee Master'!E:E,A14,'Employee Master'!K:K) | E14: Status | F14: Count
A15: Sales | B15: =COUNTIF('Employee Master'!E:E,A15) | C15: =AVERAGEIF('Employee Master'!E:E,A15,'Employee Master'!K:K) | E15: Present | F15: =COUNTIF('Attendance Tracker'!G:G,E15)
A16: Marketing | B16: =COUNTIF('Employee Master'!E:E,A16) | C16: =AVERAGEIF('Employee Master'!E:E,A16,'Employee Master'!K:K) | E16: Late | F16: =COUNTIF('Attendance Tracker'!G:G,E16)
A17: HR | B17: =COUNTIF('Employee Master'!E:E,A17) | C17: =AVERAGEIF('Employee Master'!E:E,A17,'Employee Master'!K:K) | E17: Absent | F17: =COUNTIF('Attendance Tracker'!G:G,E17)
A18: Finance | B18: =COUNTIF('Employee Master'!E:E,A18) | C18: =AVERAGEIF('Employee Master'!E:E,A18,'Employee Master'!K:K) | E18: Half Day | F18: =COUNTIF('Attendance Tracker'!G:G,E18)
A19: Operations | B19: =COUNTIF('Employee Master'!E:E,A19) | C19: =AVERAGEIF('Employee Master'!E:E,A19,'Employee Master'!K:K)

Sheet Leave Balance
A1: Employee ID | B1: Employee Name | C1: Annual Leave Total | D1: Annual Leave Used | E1: Annual Leave Balance | F1: Sick Leave Total | G1: Sick Leave Used | H1: Sick Leave Balance | I1: Casual Leave Total | J1: Casual Leave Used | K1: Casual Leave Balance
A2: EMP001 | B2: Rajesh Kumar | C2: 20 | D2: =SUMIFS('Leave Management'!F:F,'Leave Management'!A:A,A2,'Leave Management'!C:C,"Annual Leave",'Leave Management'!H:H,"Approved") | E2: =C2-D2 | F2: 12 | G2: =SUMIFS('Leave Management'!F:F,'Leave Management'!A:A,A2,'Leave Management'!C:C,"Sick Leave",'Leave Management'!H:H,"Approved") | H2: =F2-G2 | I2: 10 | J2: =SUMIFS('Leave Management'!F:F,'Leave Management'!A:A,A2,'Leave Management'!C:C,"Casual Leave",'Leave Management'!H:H,"Approved") | K2: =I2-J2
A3: EMP002 | B3: Priya Sharma | C3: 20 | D3: =SUMIFS('Leave Management'!F:F,'Leave Management'!A:A,A3,'Leave Management'!C:C,"Annual Leave",'Leave Management'!H:H,"Approved") | E3: =C3-D3 | F3: 12 | G3: =SUMIFS('Leave Management'!F:F,'Leave Management'!A:A,A3,'Leave Management'!C:C,"Sick Leave",'Leave Management'!H:H,"Approved") | H3: =F3-G3 | I3: 10 | J3: =SUMIFS('Leave Management'!F:F,'Leave Management'!A:A,A3,'Leave Management'!C:C,"Casual Leave",'Leave Management'!H:H,"Approved") | K3: =I3-J3
A4: EMP003 | B4: Amit Patel | C4: 20 | D4: =SUMIFS('Leave Management'!F:F,'Leave Management'!A:A,A4,'Leave Management'!C:C,"Annual Leave",'Leave Management'!H:H,"Approved") | E4: =C4-D4 | F4: 12 | G4: =SUMIFS('Leave Management'!F:F,'Leave Management'!A:A,A4,'Leave Management'!C:C,"Sick Leave",'Leave Management'!H:H,"Approved") | H4: =F4-G4 | I4: 10 | J4: =SUMIFS('Leave Management'!F:F,'Leave Management'!A:A,A4,'Leave Management'!C:C,"Casual Leave",'Leave Management'!H:H,"Approved") | K4: =I4-J4
A5: EMP004 | B5: Neha Singh | C5: 20 | D5: =SUMIFS('Leave Management'!F:F,'Leave Management'!A:A,A5,'Leave Management'!C:C,"Annual Leave",'Leave Management'!H:H,"Approved") | E5: =C5-D5 | F5: 12 | G5: =SUMIFS('Leave Management'!F:F,'Leave Management'!A:A,A5,'Leave Management'!C:C,"Sick Leave",'Leave Management'!H:H,"Approved") | H5: =F5-G5 | I5: 10 | J5: =SUMIFS('Leave Management'!F:F,'Leave Management'!A:A,A5,'Leave Management'!C:C,"Casual Leave",'Leave Management'!H:H,"Approved") | K5: =I5-J5
A6: EMP005 | B6: Vikram Reddy | C6: 20 | D6: =SUMIFS('Leave Management'!F:F,'Leave Management'!A:A,A6,'Leave Management'!C:C,"Annual Leave",'Leave Management'!H:H,"Approved") | E6: =C6-D6 | F6: 12 | G6: =SUMIFS('Leave Management'!F:F,'Leave Management'!A:A,A6,'Leave Management'!C:C,"Sick Leave",'Leave Management'!H:H,"Approved") | H6: =F6-G6 | I6: 10 | J6: =SUMIFS('Leave Management'!F:F,'Leave Management'!A:A,A6,'Leave Management'!C:C,"Casual Leave",'Leave Management'!H:H,"Approved") | K6: =I6-J6
A7: EMP006 | B7: Ananya Iyer | C7: 20 | D7: =SUMIFS('Leave Management'!F:F,'Leave Management'!A:A,A7,'Leave Management'!C:C,"Annual Leave",'Leave Management'!H:H,"Approved") | E7: =C7-D7 | F7: 12 | G7: =SUMIFS('Leave Management'!F:F,'Leave Management'!A:A,A7,'Leave Management'!C:C,"Sick Leave",'Leave Management'!H:H,"Approved") | H7: =F7-G7 | I7: 10 | J7: =SUMIFS('Leave Management'!F:F,'Leave Management'!A:A,A7,'Leave Management'!C:C,"Casual Leave",'Leave Management'!H:H,"Approved") | K7: =I7-J7
A8: EMP007 | B8: Karthik Menon | C8: 20 | D8: =SUMIFS('Leave Management'!F:F,'Leave Management'!A:A,A8,'Leave Management'!C:C,"Annual Leave",'Leave Management'!H:H,"Approved") | E8: =C8-D8 | F8: 12 | G8: =SUMIFS('Leave Management'!F:F,'Leave Management'!A:A,A8,'Leave Management'!C:C,"Sick Leave",'Leave Management'!H:H,"Approved") | H8: =F8-G8 | I8: 10 | J8: =SUMIFS('Leave Management'!F:F,'Leave Management'!A:A,A8,'Leave Management'!C:C,"Casual Leave",'Leave Management'!H:H,"Approved") | K8: =I8-J8
A9: EMP008 | B9: Divya Nair | C9: 20 | D9: =SUMIFS('Leave Management'!F:F,'Leave Management'!A:A,A9,'Leave Management'!C:C,"Annual Leave",'Leave Management'!H:H,"Approved") | E9: =C9-D9 | F9: 12 | G9: =SUMIFS('Leave Management'!F:F,'Leave Management'!A:A,A9,'Leave Management'!C:C,"Sick Leave",'Leave Management'!H:H,"Approved") | H9: =F9-G9 | I9: 10 | J9: =SUMIFS('Leave Management'!F:F,'Leave Management'!A:A,A9,'Leave Management'!C:C,"Casual Leave",'Leave Management'!H:H,"Approved") | K9: =I9-J9
A10: EMP009 | B10: Rahul Verma | C10: 20 | D10: =SUMIFS('Leave Management'!F:F,'Leave Management'!A:A,A10,'Leave Management'!C:C,"Annual Leave",'Leave Management'!H:H,"Approved") | E10: =C10-D10 | F10: 12 | G10: =SUMIFS('Leave Management'!F:F,'Leave Management'!A:A,A10,'Leave Management'!C:C,"Sick Leave",'Leave Management'!H:H,"Approved") | H10: =F10-G10 | I10: 10 | J10: =SUMIFS('Leave Management'!F:F,'Leave Management'!A:A,A10,'Leave Management'!C:C,"Casual Leave",'Leave Management'!H:H,"Approved") | K10: =I10-J10
A11: EMP010 | B11: Sneha Desai | C11: 20 | D11: =SUMIFS('Leave Management'!F:F,'Leave Management'!A:A,A11,'Leave Management'!C:C,"Annual Leave",'Leave Management'!H:H,"Approved") | E11: =C11-D11 | F11: 12 | G11: =SUMIFS('Leave Management'!F:F,'Leave Management'!A:A,A11,'Leave Management'!C:C,"Sick Leave",'Leave Management'!H:H,"Approved") | H11: =F11-G11 | I11: 10 | J11: =SUMIFS('Leave Management'!F:F,'Leave Management'!A:A,A11,'Leave Management'!C:C,"Casual Leave",'Leave Management'!H:H,"Approved") | K11: =I11-J11
A12: EMP011 | B12: Arjun Kapoor | C12: 20 | D12: =SUMIFS('Leave Management'!F:F,'Leave Management'!A:A,A12,'Leave Management'!C:C,"Annual Leave",'Leave Management'!H:H,"Approved") | E12: =C12-D12 | F12: 12 | G12: =SUMIFS('Leave Management'!F:F,'Leave Management'!A:A,A12,'Leave Management'!C:C,"Sick Leave",'Leave Management'!H:H,"Approved") | H12: =F12-G12 | I12: 10 | J12: =SUMIFS('Leave Management'!F:F,'Leave Management'!A:A,A12,'Leave Management'!C:C,"Casual Leave",'Leave Management'!H:H,"Approved") | K12: =I12-J12
A13: EMP012 | B13: Pooja Agarwal | C13: 20 | D13: =SUMIFS('Leave Management'!F:F,'Leave Management'!A:A,A13,'Leave Management'!C:C,"Annual Leave",'Leave Management'!H:H,"Approved") | E13: =C13-D13 | F13: 12 | G13: =SUMIFS('Leave Management'!F:F,'Leave Management'!A:A,A13,'Leave Management'!C:C,"Sick Leave",'Leave Management'!H:H,"Approved") | H13: =F13-G13 | I13: 10 | J13: =SUMIFS('Leave Management'!F:F,'Leave Management'!A:A,A13,'Leave Management'!C:C,"Casual Leave",'Leave Management'!H:H,"Approved") | K13: =I13-J13
... A16: EMP015 | B16: Siddharth Roy | C16: 20 | D16: =SUMIFS('Leave Management'!F:F,'Leave Management'!A:A,A16,'Leave Management'!C:C,"Annual Leave",'Leave Management'!H:H,"Approved") | E16: =C16-D16 | F16: 12 | G16: =SUMIFS('Leave Management'!F:F,'Leave Management'!A:A,A16,'Leave Management'!C:C,"Sick Leave",'Leave Management'!H:H,"Approved") | H16: =F16-G16 | I16: 10 | J16: =SUMIFS('Leave Management'!F:F,'Leave Management'!A:A,A16,'Leave Management'!C:C,"Casual Leave",'Leave Management'!H:H,"Approved") | K16: =I16-J16
